- crear uno nuevo mientras esta corriendo 
error Exception in Tkinter callback
Traceback (most recent call last):
  File "C:\Users\fabia\AppData\Local\Programs\Python\Python313\Lib\tkinter\__init__.py", line 2068, in __call__
    return self.func(*args)
           ~~~~~~~~~^^^^^^^
  File "c:\Users\fabia\OneDrive\Escritorio\Organizador escritorio\main.py", line 88, in iniciar_organizacion
    guardar_configuracion_bd(carpeta_destino , palabra_clave)
    ~~~~~~~~~~~~~~~~~~~~~~~~^^^^^^^^^^^^^^^^^^^^^^^^^^^^^^^^^
  File "c:\Users\fabia\OneDrive\Escritorio\Organizador escritorio\main.py", line 26, in guardar_configuracion_bd
    cursor.execute("INSERT INTO configuraciones (carpeta_destino, palabra_clave , ordenando) VALUES (?, ? , ?)",
    ~~~~~~~~~~~~~~^^^^^^^^^^^^^^^^^^^^^^^^^^^^^^^^^^^^^^^^^^^^^^^^^^^^^^^^^^^^^^^^^^^^^^^^^^^^^^^^^^^^^^^^^^^^^^
                   (carpeta_destino, palabra_clave , ordenando))
                   ^^^^^^^^^^^^^^^^^^^^^^^^^^^^^^^^^^^^^^^^^^^^^
sqlite3.OperationalError: no such table: configuraciones

